package ch12_errorhandlingwithexceptions.exercise15;
//Exercise 15: (2) Show that WithFinally.java doesnâ€™t fail by throwing a RuntimeException inside the try block.

import static thinkinginjava.Utils.print;

class Switch {
    private boolean state = false;

    public boolean read() {
        return state;
    }

    public void on() {
        state = true;
        print(this);
    }

    public void off() {
        state = false;
        print(this);
    }

    public String toString() {
        return state ? "on" : "off";
    }
}

class OnOffException1 extends Exception {
}

class OnOffException2 extends Exception {
}

public class OnOffSwitch {
    private static Switch sw = new Switch();

    public static void f()
            throws OnOffException1, OnOffException2 {
        throw new RuntimeException();
    }

    public static void main(String[] args) {
        try {
            sw.on();
            f();
        } catch(OnOffException1 e) {
            System.out.println("OnOffException1");
        } catch(OnOffException2 e) {
            System.out.println("OnOffException2");
        } finally {
            sw.off();
        }
    }
}
